Workbook

Sheet Summary
A1: Solar car outdoor drive test — 23/10/2026
A2: Source: solarcar_log_23_10_2026.csv (car_main 5 Hz log, t = 174.8–295.3 s, 603 samples). Manual mode, Drive / STOP from rest to full throttle.
A3: Sun runs were driven in clear sun; shade runs in shade. Condition is set by measured PV power (sun ≥ ~1.5 W, shade ≤ ~0.7 W mean).
A5: Assumption
A8: PV-to-battery factor (A per W of PV) | C8: 0.0815 | D8: Fitted at rest (car stopped, 325 samples): battery A = −0.0815 × PV W + 0.113, rms error 0.007 A. 0.97 W reaches the battery side per W of PV.
A9: Idle electronics current (A) | C9: 0.113 | D9: Intercept of the same fit = draw with PV ≈ 0 (≈ 1.34 W at 11.85 V).
A11: By condition
A12: Metric | B12: Sun | C12: Shade
A13: Runs (from rest) | B13: =COUNTIF(Runs!$B$2:$B$12,"Sun") -> 7 | C13: =COUNTIF(Runs!$B$2:$B$12,"Shade") -> 4
A14: Mean peak speed (m/s) | B14: =AVERAGEIFS(Runs!$G$2:$G$12,Runs!$B$2:$B$12,"Sun") -> 0.242 | C14: =AVERAGEIFS(Runs!$G$2:$G$12,Runs!$B$2:$B$12,"Shade") -> 0.7115
A15: Best peak speed (m/s) | B15: =_xlfn.MAXIFS(Runs!$G$2:$G$12,Runs!$B$2:$B$12,"Sun") -> 0.353 | C15: =_xlfn.MAXIFS(Runs!$G$2:$G$12,Runs!$B$2:$B$12,"Shade") -> 0.735
A16: Mean time to 90 % of peak (s) | B16: =AVERAGEIFS(Runs!$H$2:$H$12,Runs!$B$2:$B$12,"Sun") -> 1.9985714 | C16: =AVERAGEIFS(Runs!$H$2:$H$12,Runs!$B$2:$B$12,"Shade") -> 1.2
A17: Total distance (m) | B17: =SUMIFS(Runs!$J$2:$J$12,Runs!$B$2:$B$12,"Sun") -> 2.79358 | C17: =SUMIFS(Runs!$J$2:$J$12,Runs!$B$2:$B$12,"Shade") -> 10.82953
A18: Mean load power while driving (W) | B18: =AVERAGEIFS(Runs!$M$2:$M$12,Runs!$B$2:$B$12,"Sun") -> 5.9372599 | C18: =AVERAGEIFS(Runs!$M$2:$M$12,Runs!$B$2:$B$12,"Shade") -> 6.492049
A19: Mean PV power while driving (W) | B19: =AVERAGEIFS(Runs!$Q$2:$Q$12,Runs!$B$2:$B$12,"Sun") -> 4.262519 | C19: =AVERAGEIFS(Runs!$Q$2:$Q$12,Runs!$B$2:$B$12,"Shade") -> 0.29250188
A20: Mean peak battery current (A) | B20: =AVERAGEIFS(Runs!$K$2:$K$12,Runs!$B$2:$B$12,"Sun") -> 0.666 | C20: =AVERAGEIFS(Runs!$K$2:$K$12,Runs!$B$2:$B$12,"Shade") -> 0.9585
A21: Mean voltage sag at start (V) | B21: =AVERAGEIFS(Runs!$P$2:$P$12,Runs!$B$2:$B$12,"Sun") -> 0.31428571 | C21: =AVERAGEIFS(Runs!$P$2:$P$12,Runs!$B$2:$B$12,"Shade") -> 0.30925
A22: Total load energy (J) | B22: =SUMIFS(Runs!$R$2:$R$12,Runs!$B$2:$B$12,"Sun") -> 146.16207 | C22: =SUMIFS(Runs!$R$2:$R$12,Runs!$B$2:$B$12,"Shade") -> 128.87258
A23: Total battery energy (J) | B23: =SUMIFS(Runs!$S$2:$S$12,Runs!$B$2:$B$12,"Sun") -> 30.730873 | C23: =SUMIFS(Runs!$S$2:$S$12,Runs!$B$2:$B$12,"Shade") -> 123.25541
A24: Share of driving energy from solar | B24: =IF(B22>0,1-B23/B22,"") -> 0.78974796 | C24: =IF(C22>0,1-C23/C22,"") -> 0.04358703
A25: Energy per metre, runs ≥ 1 m (J/m) | B25: =IFERROR(AVERAGEIFS(Runs!$U$2:$U$12,Runs!$B$2:$B$12,"Sun"),"n/a") -> n/a | C25: =IFERROR(AVERAGEIFS(Runs!$U$2:$U$12,Runs!$B$2:$B$12,"Shade"),"n/a") -> 11.489988
A27: Observations
A28: • In the sun the panels supplied most of the driving energy: the battery barely discharged (see the share row and Charts - Sun). Parked in the sun the pack charged at ~0.3 A net (~5 W PV).
A29: • In shade (PV ≈ 0.1 W) the battery supplied ~all of the 6–7 W load; the car reached ~0.7 m/s within ~1 s and used ~11 J per metre.
A30: • Parked in the sun (2 stationary tests, Charging sheet): about 4.8–5.7 W of PV, about 1.3 W used by the electronics and 3.3–4.2 W going into the pack (about 0.28–0.35 A).
A31: • Sun runs drew a similar load (~5–7 W) but only reached 0.12–0.35 m/s. Throttle is not in the log, so this cannot yet be separated from a lower throttle, surface or slope — log the throttle % next time.
A32: • PV power fell from ~5.7 W to ~4 W during the sun driving and recovered when parked (heading change or tracker parking the panel while moving).
A33: • Start-up current peaks of 0.5–1.1 A sag the pack by 0.25–0.41 V; no resets, no low-voltage lock.
A34: • Link-loss stop seen once (t = 251.9–260.5 s, parked in shade): failsafe flag set, gear forced to STOP.
A35: • Not used in the analysis: one Drive press at t = 179.4 s with no movement; rear ultrasonic (dB) not connected; Copilot correction was 0 (Manual mode).
A37: Stationary charging in the sun
A38: Metric | B38: Mean of tests
A39: Tests | B39: =COUNTA(Charging!$A$2:$A$3) -> 2
A40: Total time (s) | B40: =SUM(Charging!$D$2:$D$3) -> 21.99
A41: PV power (W) | B41: =AVERAGE(Charging!$E$2:$E$3) -> 5.2508263
A42: Power into battery (W) | B42: =AVERAGE(Charging!$H$2:$H$3) -> 3.7621043
A43: Electronics load (W) | B43: =AVERAGE(Charging!$I$2:$I$3) -> 1.3594898
A44: Share of PV reaching battery | B44: =AVERAGE(Charging!$K$2:$K$3) -> 0.7144096

Sheet Runs
A1: Run | B1: Condition | C1: Start (s) | D1: Drive released (s) | E1: Stopped (s) | F1: Drive time (s) | G1: Peak speed (m/s) | H1: Time to 90 % of peak (s) | I1: Mean speed (m/s) | J1: Distance (m) | K1: Peak battery current (A) | L1: Mean load current (A) | M1: Mean load power (W) | N1: Min pack voltage (V) | O1: Pack voltage before start (V) | P1: Voltage sag (V) | Q1: Mean PV power (W) | R1: Load energy (J) | S1: Battery energy (J) | T1: Share supplied by solar | U1: Energy per metre (J/m) | V1: Notes
A2: Sun 1 | B2: Sun | C2: 181.64 | D2: 189.24 | E2: 189.64 | F2: =D2-C2+0.2 -> 7.8 | G2: =_xlfn.MAXIFS(Data!$E$2:$E$604,Data!$A$2:$A$604,">="&C2,Data!$A$2:$A$604,"<="&E2) -> 0.136 | H2: 1 | I2: =AVERAGEIFS(Data!$E$2:$E$604,Data!$A$2:$A$604,">="&C2,Data!$A$2:$A$604,"<="&D2) -> 0.016307692 | J2: =SUMPRODUCT((Data!$A$2:$A$604>=C2)*(Data!$A$2:$A$604<=E2)*Data!$E$2:$E$604*Data!$S$2:$S$604) -> 0.138 | K2: =_xlfn.MAXIFS(Data!$C$2:$C$604,Data!$A$2:$A$604,">="&C2,Data!$A$2:$A$604,"<="&D2) -> 0.509 | L2: =AVERAGEIFS(Data!$T$2:$T$604,Data!$A$2:$A$604,">="&C2,Data!$A$2:$A$604,"<="&D2) -> 0.41039321 | M2: =AVERAGEIFS(Data!$U$2:$U$604,Data!$A$2:$A$604,">="&C2,Data!$A$2:$A$604,"<="&D2) -> 4.8604704 | N2: =_xlfn.MINIFS(Data!$B$2:$B$604,Data!$A$2:$A$604,">="&C2,Data!$A$2:$A$604,"<="&D2) -> 11.691 | O2: =INDEX(Data!$B$2:$B$604,MATCH(C2,Data!$A$2:$A$604,0)-1) -> 11.984 | P2: =O2-N2 -> 0.293 | Q2: =AVERAGEIFS(Data!$D$2:$D$604,Data!$A$2:$A$604,">="&C2,Data!$A$2:$A$604,"<="&D2) -> 5.284359 | R2: =SUMPRODUCT((Data!$A$2:$A$604>=C2)*(Data!$A$2:$A$604<=D2)*Data!$U$2:$U$604*Data!$S$2:$S$604) -> 37.924367 | S2: =SUMPRODUCT((Data!$A$2:$A$604>=C2)*(Data!$A$2:$A$604<=D2)*Data!$V$2:$V$604*Data!$S$2:$S$604) -> -1.942148 | T2: =IF(R2>0,1-S2/R2,"") -> 1.0512111 | U2: =IF(J2>=1,R2/J2,"") | V2: Crept forward only (0.14 m); little or no throttle for most of the 7.8 s.
A3: Sun 2 | B3: Sun | C3: 190.24 | D3: 192.64 | E3: 193.44 | F3: =D3-C3+0.2 -> 2.6 | G3: =_xlfn.MAXIFS(Data!$E$2:$E$604,Data!$A$2:$A$604,">="&C3,Data!$A$2:$A$604,"<="&E3) -> 0.245 | H3: 1 | I3: =AVERAGEIFS(Data!$E$2:$E$604,Data!$A$2:$A$604,">="&C3,Data!$A$2:$A$604,"<="&D3) -> 0.14930769 | J3: =SUMPRODUCT((Data!$A$2:$A$604>=C3)*(Data!$A$2:$A$604<=E3)*Data!$E$2:$E$604*Data!$S$2:$S$604) -> 0.4804 | K3: =_xlfn.MAXIFS(Data!$C$2:$C$604,Data!$A$2:$A$604,">="&C3,Data!$A$2:$A$604,"<="&D3) -> 0.643 | L3: =AVERAGEIFS(Data!$T$2:$T$604,Data!$A$2:$A$604,">="&C3,Data!$A$2:$A$604,"<="&D3) -> 0.57088354 | M3: =AVERAGEIFS(Data!$U$2:$U$604,Data!$A$2:$A$604,">="&C3,Data!$A$2:$A$604,"<="&D3) -> 6.7150766 | N3: =_xlfn.MINIFS(Data!$B$2:$B$604,Data!$A$2:$A$604,">="&C3,Data!$A$2:$A$604,"<="&D3) -> 11.661 | O3: =INDEX(Data!$B$2:$B$604,MATCH(C3,Data!$A$2:$A$604,0)-1) -> 11.952 | P3: =O3-N3 -> 0.291 | Q3: =AVERAGEIFS(Data!$D$2:$D$604,Data!$A$2:$A$604,">="&C3,Data!$A$2:$A$604,"<="&D3) -> 4.3572308 | R3: =SUMPRODUCT((Data!$A$2:$A$604>=C3)*(Data!$A$2:$A$604<=D3)*Data!$U$2:$U$604*Data!$S$2:$S$604) -> 17.459199 | S3: =SUMPRODUCT((Data!$A$2:$A$604>=C3)*(Data!$A$2:$A$604<=D3)*Data!$V$2:$V$604*Data!$S$2:$S$604) -> 6.5728402 | T3: =IF(R3>0,1-S3/R3,"") -> 0.6235314 | U3: =IF(J3>=1,R3/J3,"")
A4: Sun 3 | B4: Sun | C4: 193.84 | D4: 201.04 | E4: 201.84 | F4: =D4-C4+0.2 -> 7.4 | G4: =_xlfn.MAXIFS(Data!$E$2:$E$604,Data!$A$2:$A$604,">="&C4,Data!$A$2:$A$604,"<="&E4) -> 0.299 | H4: 7 | I4: =AVERAGEIFS(Data!$E$2:$E$604,Data!$A$2:$A$604,">="&C4,Data!$A$2:$A$604,"<="&D4) -> 0.093432432 | J4: =SUMPRODUCT((Data!$A$2:$A$604>=C4)*(Data!$A$2:$A$604<=E4)*Data!$E$2:$E$604*Data!$S$2:$S$604) -> 0.8054 | K4: =_xlfn.MAXIFS(Data!$C$2:$C$604,Data!$A$2:$A$604,">="&C4,Data!$A$2:$A$604,"<="&D4) -> 0.482 | L4: =AVERAGEIFS(Data!$T$2:$T$604,Data!$A$2:$A$604,">="&C4,Data!$A$2:$A$604,"<="&D4) -> 0.45282939 | M4: =AVERAGEIFS(Data!$U$2:$U$604,Data!$A$2:$A$604,">="&C4,Data!$A$2:$A$604,"<="&D4) -> 5.3390289 | N4: =_xlfn.MINIFS(Data!$B$2:$B$604,Data!$A$2:$A$604,">="&C4,Data!$A$2:$A$604,"<="&D4) -> 11.663 | O4: =INDEX(Data!$B$2:$B$604,MATCH(C4,Data!$A$2:$A$604,0)-1) -> 11.918 | P4: =O4-N4 -> 0.255 | Q4: =AVERAGEIFS(Data!$D$2:$D$604,Data!$A$2:$A$604,">="&C4,Data!$A$2:$A$604,"<="&D4) -> 4.1385135 | R4: =SUMPRODUCT((Data!$A$2:$A$604>=C4)*(Data!$A$2:$A$604<=D4)*Data!$U$2:$U$604*Data!$S$2:$S$604) -> 39.508814 | S4: =SUMPRODUCT((Data!$A$2:$A$604>=C4)*(Data!$A$2:$A$604<=D4)*Data!$V$2:$V$604*Data!$S$2:$S$604) -> 10.018439 | T4: =IF(R4>0,1-S4/R4,"") -> 0.74642522 | U4: =IF(J4>=1,R4/J4,"")
A5: Sun 4 | B5: Sun | C5: 219.24 | D5: 222.45 | E5: 222.85 | F5: =D5-C5+0.2 -> 3.41 | G5: =_xlfn.MAXIFS(Data!$E$2:$E$604,Data!$A$2:$A$604,">="&C5,Data!$A$2:$A$604,"<="&E5) -> 0.118 | H5: 2.6 | I5: =AVERAGEIFS(Data!$E$2:$E$604,Data!$A$2:$A$604,">="&C5,Data!$A$2:$A$604,"<="&D5) -> 0.020176471 | J5: =SUMPRODUCT((Data!$A$2:$A$604>=C5)*(Data!$A$2:$A$604<=E5)*Data!$E$2:$E$604*Data!$S$2:$S$604) -> 0.07778 | K5: =_xlfn.MAXIFS(Data!$C$2:$C$604,Data!$A$2:$A$604,">="&C5,Data!$A$2:$A$604,"<="&D5) -> 0.49 | L5: =AVERAGEIFS(Data!$T$2:$T$604,Data!$A$2:$A$604,">="&C5,Data!$A$2:$A$604,"<="&D5) -> 0.43383482 | M5: =AVERAGEIFS(Data!$U$2:$U$604,Data!$A$2:$A$604,">="&C5,Data!$A$2:$A$604,"<="&D5) -> 5.1315797 | N5: =_xlfn.MINIFS(Data!$B$2:$B$604,Data!$A$2:$A$604,">="&C5,Data!$A$2:$A$604,"<="&D5) -> 11.714 | O5: =INDEX(Data!$B$2:$B$604,MATCH(C5,Data!$A$2:$A$604,0)-1) -> 11.971 | P5: =O5-N5 -> 0.257 | Q5: =AVERAGEIFS(Data!$D$2:$D$604,Data!$A$2:$A$604,">="&C5,Data!$A$2:$A$604,"<="&D5) -> 5.1275294 | R5: =SUMPRODUCT((Data!$A$2:$A$604>=C5)*(Data!$A$2:$A$604<=D5)*Data!$U$2:$U$604*Data!$S$2:$S$604) -> 17.474101 | S5: =SUMPRODUCT((Data!$A$2:$A$604>=C5)*(Data!$A$2:$A$604<=D5)*Data!$V$2:$V$604*Data!$S$2:$S$604) -> 0.58471163 | T5: =IF(R5>0,1-S5/R5,"") -> 0.96653839 | U5: =IF(J5>=1,R5/J5,"") | V5: Short creep (0.08 m).
A6: Sun 5 | B6: Sun | C6: 223.27 | D6: 224.86 | E6: 225.66 | F6: =D6-C6+0.2 -> 1.79 | G6: =_xlfn.MAXIFS(Data!$E$2:$E$604,Data!$A$2:$A$604,">="&C6,Data!$A$2:$A$604,"<="&E6) -> 0.217 | H6: 0.59 | I6: =AVERAGEIFS(Data!$E$2:$E$604,Data!$A$2:$A$604,">="&C6,Data!$A$2:$A$604,"<="&D6) -> 0.14466667 | J6: =SUMPRODUCT((Data!$A$2:$A$604>=C6)*(Data!$A$2:$A$604<=E6)*Data!$E$2:$E$604*Data!$S$2:$S$604) -> 0.3336 | K6: =_xlfn.MAXIFS(Data!$C$2:$C$604,Data!$A$2:$A$604,">="&C6,Data!$A$2:$A$604,"<="&D6) -> 0.877 | L6: =AVERAGEIFS(Data!$T$2:$T$604,Data!$A$2:$A$604,">="&C6,Data!$A$2:$A$604,"<="&D6) -> 0.54656489 | M6: =AVERAGEIFS(Data!$U$2:$U$604,Data!$A$2:$A$604,">="&C6,Data!$A$2:$A$604,"<="&D6) -> 6.4176041 | N6: =_xlfn.MINIFS(Data!$B$2:$B$604,Data!$A$2:$A$604,">="&C6,Data!$A$2:$A$604,"<="&D6) -> 11.55 | O6: =INDEX(Data!$B$2:$B$604,MATCH(C6,Data!$A$2:$A$604,0)-1) -> 11.952 | P6: =O6-N6 -> 0.402 | Q6: =AVERAGEIFS(Data!$D$2:$D$604,Data!$A$2:$A$604,">="&C6,Data!$A$2:$A$604,"<="&D6) -> 4.4595556 | R6: =SUMPRODUCT((Data!$A$2:$A$604>=C6)*(Data!$A$2:$A$604<=D6)*Data!$U$2:$U$604*Data!$S$2:$S$604) -> 11.526296 | S6: =SUMPRODUCT((Data!$A$2:$A$604>=C6)*(Data!$A$2:$A$604<=D6)*Data!$V$2:$V$604*Data!$S$2:$S$604) -> 3.8569114 | T6: =IF(R6>0,1-S6/R6,"") -> 0.66538156 | U6: =IF(J6>=1,R6/J6,"")
A7: Sun 6 | B7: Sun | C7: 225.86 | D7: 227.46 | E7: 228.26 | F7: =D7-C7+0.2 -> 1.8 | G7: =_xlfn.MAXIFS(Data!$E$2:$E$604,Data!$A$2:$A$604,">="&C7,Data!$A$2:$A$604,"<="&E7) -> 0.326 | H7: 1 | I7: =AVERAGEIFS(Data!$E$2:$E$604,Data!$A$2:$A$604,">="&C7,Data!$A$2:$A$604,"<="&D7) -> 0.22022222 | J7: =SUMPRODUCT((Data!$A$2:$A$604>=C7)*(Data!$A$2:$A$604<=E7)*Data!$E$2:$E$604*Data!$S$2:$S$604) -> 0.4642 | K7: =_xlfn.MAXIFS(Data!$C$2:$C$604,Data!$A$2:$A$604,">="&C7,Data!$A$2:$A$604,"<="&D7) -> 0.985 | L7: =AVERAGEIFS(Data!$T$2:$T$604,Data!$A$2:$A$604,">="&C7,Data!$A$2:$A$604,"<="&D7) -> 0.56126078 | M7: =AVERAGEIFS(Data!$U$2:$U$604,Data!$A$2:$A$604,">="&C7,Data!$A$2:$A$604,"<="&D7) -> 6.5699819 | N7: =_xlfn.MINIFS(Data!$B$2:$B$604,Data!$A$2:$A$604,">="&C7,Data!$A$2:$A$604,"<="&D7) -> 11.526 | O7: =INDEX(Data!$B$2:$B$604,MATCH(C7,Data!$A$2:$A$604,0)-1) -> 11.933 | P7: =O7-N7 -> 0.407 | Q7: =AVERAGEIFS(Data!$D$2:$D$604,Data!$A$2:$A$604,">="&C7,Data!$A$2:$A$604,"<="&D7) -> 3.7264444 | R7: =SUMPRODUCT((Data!$A$2:$A$604>=C7)*(Data!$A$2:$A$604<=D7)*Data!$U$2:$U$604*Data!$S$2:$S$604) -> 11.825967 | S7: =SUMPRODUCT((Data!$A$2:$A$604>=C7)*(Data!$A$2:$A$604<=D7)*Data!$V$2:$V$604*Data!$S$2:$S$604) -> 5.3974354 | T7: =IF(R7>0,1-S7/R7,"") -> 0.5435946 | U7: =IF(J7>=1,R7/J7,"")
A8: Sun 7 | B8: Sun | C8: 228.86 | D8: 230.26 | E8: 231.26 | F8: =D8-C8+0.2 -> 1.6 | G8: =_xlfn.MAXIFS(Data!$E$2:$E$604,Data!$A$2:$A$604,">="&C8,Data!$A$2:$A$604,"<="&E8) -> 0.353 | H8: 0.8 | I8: =AVERAGEIFS(Data!$E$2:$E$604,Data!$A$2:$A$604,">="&C8,Data!$A$2:$A$604,"<="&D8) -> 0.229125 | J8: =SUMPRODUCT((Data!$A$2:$A$604>=C8)*(Data!$A$2:$A$604<=E8)*Data!$E$2:$E$604*Data!$S$2:$S$604) -> 0.4942 | K8: =_xlfn.MAXIFS(Data!$C$2:$C$604,Data!$A$2:$A$604,">="&C8,Data!$A$2:$A$604,"<="&D8) -> 0.676 | L8: =AVERAGEIFS(Data!$T$2:$T$604,Data!$A$2:$A$604,">="&C8,Data!$A$2:$A$604,"<="&D8) -> 0.556636 | M8: =AVERAGEIFS(Data!$U$2:$U$604,Data!$A$2:$A$604,">="&C8,Data!$A$2:$A$604,"<="&D8) -> 6.5270776 | N8: =_xlfn.MINIFS(Data!$B$2:$B$604,Data!$A$2:$A$604,">="&C8,Data!$A$2:$A$604,"<="&D8) -> 11.616 | O8: =INDEX(Data!$B$2:$B$604,MATCH(C8,Data!$A$2:$A$604,0)-1) -> 11.911 | P8: =O8-N8 -> 0.295 | Q8: =AVERAGEIFS(Data!$D$2:$D$604,Data!$A$2:$A$604,">="&C8,Data!$A$2:$A$604,"<="&D8) -> 2.744 | R8: =SUMPRODUCT((Data!$A$2:$A$604>=C8)*(Data!$A$2:$A$604<=D8)*Data!$U$2:$U$604*Data!$S$2:$S$604) -> 10.443324 | S8: =SUMPRODUCT((Data!$A$2:$A$604>=C8)*(Data!$A$2:$A$604<=D8)*Data!$V$2:$V$604*Data!$S$2:$S$604) -> 6.2426836 | T8: =IF(R8>0,1-S8/R8,"") -> 0.40223213 | U8: =IF(J8>=1,R8/J8,"") | V8: Driven into the shade: PV fell from 3.4 to 1.2 W during the run.
A9: Shade 1 | B9: Shade | C9: 263.06 | D9: 274.88 | E9: 275.68 | F9: =D9-C9+0.2 -> 12.02 | G9: =_xlfn.MAXIFS(Data!$E$2:$E$604,Data!$A$2:$A$604,">="&C9,Data!$A$2:$A$604,"<="&E9) -> 0.721 | H9: 1.62 | I9: =AVERAGEIFS(Data!$E$2:$E$604,Data!$A$2:$A$604,">="&C9,Data!$A$2:$A$604,"<="&D9) -> 0.46963333 | J9: =SUMPRODUCT((Data!$A$2:$A$604>=C9)*(Data!$A$2:$A$604<=E9)*Data!$E$2:$E$604*Data!$S$2:$S$604) -> 5.78855 | K9: =_xlfn.MAXIFS(Data!$C$2:$C$604,Data!$A$2:$A$604,">="&C9,Data!$A$2:$A$604,"<="&D9) -> 0.85 | L9: =AVERAGEIFS(Data!$T$2:$T$604,Data!$A$2:$A$604,">="&C9,Data!$A$2:$A$604,"<="&D9) -> 0.52113734 | M9: =AVERAGEIFS(Data!$U$2:$U$604,Data!$A$2:$A$604,">="&C9,Data!$A$2:$A$604,"<="&D9) -> 6.0788142 | N9: =_xlfn.MINIFS(Data!$B$2:$B$604,Data!$A$2:$A$604,">="&C9,Data!$A$2:$A$604,"<="&D9) -> 11.526 | O9: =INDEX(Data!$B$2:$B$604,MATCH(C9,Data!$A$2:$A$604,0)-1) -> 11.81 | P9: =O9-N9 -> 0.284 | Q9: =AVERAGEIFS(Data!$D$2:$D$604,Data!$A$2:$A$604,">="&C9,Data!$A$2:$A$604,"<="&D9) -> 0.26978333 | R9: =SUMPRODUCT((Data!$A$2:$A$604>=C9)*(Data!$A$2:$A$604<=D9)*Data!$U$2:$U$604*Data!$S$2:$S$604) -> 73.046939 | S9: =SUMPRODUCT((Data!$A$2:$A$604>=C9)*(Data!$A$2:$A$604<=D9)*Data!$V$2:$V$604*Data!$S$2:$S$604) -> 69.951744 | T9: =IF(R9>0,1-S9/R9,"") -> 0.042372683 | U9: =IF(J9>=1,R9/J9,"") -> 12.619212 | V9: Longest run (5.8 m); speed dips to ~0.35–0.45 m/s mid-run (steering / brief sun patch at 265.9 s).
A10: Shade 2 | B10: Shade | C10: 275.88 | D10: 278.68 | E10: 279.68 | F10: =D10-C10+0.2 -> 3 | G10: =_xlfn.MAXIFS(Data!$E$2:$E$604,Data!$A$2:$A$604,">="&C10,Data!$A$2:$A$604,"<="&E10) -> 0.735 | H10: 1.4 | I10: =AVERAGEIFS(Data!$E$2:$E$604,Data!$A$2:$A$604,">="&C10,Data!$A$2:$A$604,"<="&D10) -> 0.45873333 | J10: =SUMPRODUCT((Data!$A$2:$A$604>=C10)*(Data!$A$2:$A$604<=E10)*Data!$E$2:$E$604*Data!$S$2:$S$604) -> 1.5638 | K10: =_xlfn.MAXIFS(Data!$C$2:$C$604,Data!$A$2:$A$604,">="&C10,Data!$A$2:$A$604,"<="&D10) -> 0.931 | L10: =AVERAGEIFS(Data!$T$2:$T$604,Data!$A$2:$A$604,">="&C10,Data!$A$2:$A$604,"<="&D10) -> 0.55446793 | M10: =AVERAGEIFS(Data!$U$2:$U$604,Data!$A$2:$A$604,">="&C10,Data!$A$2:$A$604,"<="&D10) -> 6.4598852 | N10: =_xlfn.MINIFS(Data!$B$2:$B$604,Data!$A$2:$A$604,">="&C10,Data!$A$2:$A$604,"<="&D10) -> 11.51 | O10: =INDEX(Data!$B$2:$B$604,MATCH(C10,Data!$A$2:$A$604,0)-1) -> 11.814 | P10: =O10-N10 -> 0.304 | Q10: =AVERAGEIFS(Data!$D$2:$D$604,Data!$A$2:$A$604,">="&C10,Data!$A$2:$A$604,"<="&D10) -> 0.7084 | R10: =SUMPRODUCT((Data!$A$2:$A$604>=C10)*(Data!$A$2:$A$604<=D10)*Data!$U$2:$U$604*Data!$S$2:$S$604) -> 19.379656 | S10: =SUMPRODUCT((Data!$A$2:$A$604>=C10)*(Data!$A$2:$A$604<=D10)*Data!$V$2:$V$604*Data!$S$2:$S$604) -> 17.360405 | T10: =IF(R10>0,1-S10/R10,"") -> 0.10419436 | U10: =IF(J10>=1,R10/J10,"") -> 12.392669
A11: Shade 3 | B11: Shade | C11: 279.88 | D11: 282.51 | E11: 283.3 | F11: =D11-C11+0.2 -> 2.83 | G11: =_xlfn.MAXIFS(Data!$E$2:$E$604,Data!$A$2:$A$604,">="&C11,Data!$A$2:$A$604,"<="&E11) -> 0.694 | H11: 0.8 | I11: =AVERAGEIFS(Data!$E$2:$E$604,Data!$A$2:$A$604,">="&C11,Data!$A$2:$A$604,"<="&D11) -> 0.5295 | J11: =SUMPRODUCT((Data!$A$2:$A$604>=C11)*(Data!$A$2:$A$604<=E11)*Data!$E$2:$E$604*Data!$S$2:$S$604) -> 1.80229 | K11: =_xlfn.MAXIFS(Data!$C$2:$C$604,Data!$A$2:$A$604,">="&C11,Data!$A$2:$A$604,"<="&D11) -> 0.941 | L11: =AVERAGEIFS(Data!$T$2:$T$604,Data!$A$2:$A$604,">="&C11,Data!$A$2:$A$604,"<="&D11) -> 0.58704407 | M11: =AVERAGEIFS(Data!$U$2:$U$604,Data!$A$2:$A$604,">="&C11,Data!$A$2:$A$604,"<="&D11) -> 6.8186921 | N11: =_xlfn.MINIFS(Data!$B$2:$B$604,Data!$A$2:$A$604,">="&C11,Data!$A$2:$A$604,"<="&D11) -> 11.489 | O11: =INDEX(Data!$B$2:$B$604,MATCH(C11,Data!$A$2:$A$604,0)-1) -> 11.797 | P11: =O11-N11 -> 0.308 | Q11: =AVERAGEIFS(Data!$D$2:$D$604,Data!$A$2:$A$604,">="&C11,Data!$A$2:$A$604,"<="&D11) -> 0.15128571 | R11: =SUMPRODUCT((Data!$A$2:$A$604>=C11)*(Data!$A$2:$A$604<=D11)*Data!$U$2:$U$604*Data!$S$2:$S$604) -> 19.243343 | S11: =SUMPRODUCT((Data!$A$2:$A$604>=C11)*(Data!$A$2:$A$604<=D11)*Data!$V$2:$V$604*Data!$S$2:$S$604) -> 18.840017 | T11: =IF(R11>0,1-S11/R11,"") -> 0.020959255 | U11: =IF(J11>=1,R11/J11,"") -> 10.677163
A12: Shade 4 | B12: Shade | C12: 283.52 | D12: 285.91 | E12: 286.91 | F12: =D12-C12+0.2 -> 2.59 | G12: =_xlfn.MAXIFS(Data!$E$2:$E$604,Data!$A$2:$A$604,">="&C12,Data!$A$2:$A$604,"<="&E12) -> 0.696 | H12: 0.98 | I12: =AVERAGEIFS(Data!$E$2:$E$604,Data!$A$2:$A$604,">="&C12,Data!$A$2:$A$604,"<="&D12) -> 0.54207692 | J12: =SUMPRODUCT((Data!$A$2:$A$604>=C12)*(Data!$A$2:$A$604<=E12)*Data!$E$2:$E$604*Data!$S$2:$S$604) -> 1.67489 | K12: =_xlfn.MAXIFS(Data!$C$2:$C$604,Data!$A$2:$A$604,">="&C12,Data!$A$2:$A$604,"<="&D12) -> 1.112 | L12: =AVERAGEIFS(Data!$T$2:$T$604,Data!$A$2:$A$604,">="&C12,Data!$A$2:$A$604,"<="&D12) -> 0.56976542 | M12: =AVERAGEIFS(Data!$U$2:$U$604,Data!$A$2:$A$604,">="&C12,Data!$A$2:$A$604,"<="&D12) -> 6.6108044 | N12: =_xlfn.MINIFS(Data!$B$2:$B$604,Data!$A$2:$A$604,">="&C12,Data!$A$2:$A$604,"<="&D12) -> 11.449 | O12: =INDEX(Data!$B$2:$B$604,MATCH(C12,Data!$A$2:$A$604,0)-1) -> 11.79 | P12: =O12-N12 -> 0.341 | Q12: =AVERAGEIFS(Data!$D$2:$D$604,Data!$A$2:$A$604,">="&C12,Data!$A$2:$A$604,"<="&D12) -> 0.040538462 | R12: =SUMPRODUCT((Data!$A$2:$A$604>=C12)*(Data!$A$2:$A$604<=D12)*Data!$U$2:$U$604*Data!$S$2:$S$604) -> 17.202644 | S12: =SUMPRODUCT((Data!$A$2:$A$604>=C12)*(Data!$A$2:$A$604<=D12)*Data!$V$2:$V$604*Data!$S$2:$S$604) -> 17.103242 | T12: =IF(R12>0,1-S12/R12,"") -> 0.0057782606 | U12: =IF(J12>=1,R12/J12,"") -> 10.27091

Sheet Charging
A1: Test | B1: Start (s) | C1: End (s) | D1: Duration (s) | E1: Mean PV power (W) | F1: Mean battery current (A) | G1: Mean pack voltage (V) | H1: Power into battery (W) | I1: Electronics load (W) | J1: Energy into battery (J) | K1: Share of PV reaching battery | L1: Share of PV used by electronics | M1: Notes
A2: Charge 1 | B2: 174.84 | C2: 179.23 | D2: =C2-B2+0.2 -> 4.59 | E2: =AVERAGEIFS(Data!$D$2:$D$604,Data!$A$2:$A$604,">="&B2,Data!$A$2:$A$604,"<="&C2) -> 5.7250435 | F2: =AVERAGEIFS(Data!$C$2:$C$604,Data!$A$2:$A$604,">="&B2,Data!$A$2:$A$604,"<="&C2) -> -0.35234783 | G2: =AVERAGEIFS(Data!$B$2:$B$604,Data!$A$2:$A$604,">="&B2,Data!$A$2:$A$604,"<="&C2) -> 11.980087 | H2: =-AVERAGEIFS(Data!$V$2:$V$604,Data!$A$2:$A$604,">="&B2,Data!$A$2:$A$604,"<="&C2) -> 4.2211775 | I2: =AVERAGEIFS(Data!$U$2:$U$604,Data!$A$2:$A$604,">="&B2,Data!$A$2:$A$604,"<="&C2) -> 1.368638 | J2: =-SUMPRODUCT((Data!$A$2:$A$604>=B2)*(Data!$A$2:$A$604<=C2)*Data!$V$2:$V$604*Data!$S$2:$S$604) -> 19.41442 | K2: =IF(E2>0,H2/E2,"") -> 0.73731798 | L2: =IF(E2>0,I2/E2,"") -> 0.23906158 | M2: Parked in sun before the first drive (log starts at 174.8 s).
A3: Charge 2 | B3: 201.84 | C3: 219.04 | D3: =C3-B3+0.2 -> 17.4 | E3: =AVERAGEIFS(Data!$D$2:$D$604,Data!$A$2:$A$604,">="&B3,Data!$A$2:$A$604,"<="&C3) -> 4.7766092 | F3: =AVERAGEIFS(Data!$C$2:$C$604,Data!$A$2:$A$604,">="&B3,Data!$A$2:$A$604,"<="&C3) -> -0.27629885 | G3: =AVERAGEIFS(Data!$B$2:$B$604,Data!$A$2:$A$604,">="&B3,Data!$A$2:$A$604,"<="&C3) -> 11.950437 | H3: =-AVERAGEIFS(Data!$V$2:$V$604,Data!$A$2:$A$604,">="&B3,Data!$A$2:$A$604,"<="&C3) -> 3.3030311 | I3: =AVERAGEIFS(Data!$U$2:$U$604,Data!$A$2:$A$604,">="&B3,Data!$A$2:$A$604,"<="&C3) -> 1.3503416 | J3: =-SUMPRODUCT((Data!$A$2:$A$604>=B3)*(Data!$A$2:$A$604<=C3)*Data!$V$2:$V$604*Data!$S$2:$S$604) -> 57.472741 | K3: =IF(E3>0,H3/E3,"") -> 0.69150122 | L3: =IF(E3>0,I3/E3,"") -> 0.28269877 | M3: Parked in sun between sun runs 3 and 4; one PV glitch at 213.8 s (0.4 W for one sample).
A5: Into battery + electronics load ≈ PV x 0.97: the solar power that is not used by the electronics goes into the pack.

Sheet Data
A1: t_s | B1: pack_V | C1: pack_A | D1: pv_W | E1: speed_mps | F1: soc_pct | G1: dF_cm | H1: dL_cm | I1: dR_cm | J1: dB_cm | K1: gear | L1: driving | M1: failsafe | N1: copilot_block | O1: lv_lock | P1: bat_ok | Q1: pv_ok | R1: copilot_u | S1: dt_s | T1: I_load_A | U1: P_load_W | V1: P_pack_W | W1: run | X1: condition
A2: 174.84 | B2: 11.977 | C2: -0.345 | D2: 5.611 | E2: 0 | F2: 76 | G2: 400 | H2: 124 | I2: 400 | K2: 1 | L2: 0 | M2: 0 | N2: 0 | O2: 0 | P2: 1 | Q2: 1 | R2: 0 | S2: =A3-A2 -> 0.19 | T2: =C2+Summary!$C$8*D2 -> 0.1122965 | U2: =B2*T2 -> 1.3449752 | V2: =B2*C2 -> -4.132065
A3: 175.03 | B3: 11.977 | C3: -0.345 | D3: 5.605 | E3: 0 | F3: 76 | G3: 400 | H3: 124 | I3: 400 | K3: 1 | L3: 0 | M3: 0 | N3: 0 | O3: 0 | P3: 1 | Q3: 1 | R3: 0 | S3: =A4-A3 -> 0.21 | T3: =C3+Summary!$C$8*D3 -> 0.1118075 | U3: =B3*T3 -> 1.3391184 | V3: =B3*C3 -> -4.132065
A4: 175.24 | B4: 11.973 | C4: -0.345 | D4: 5.612 | E4: 0 | F4: 76 | G4: 400 | H4: 125 | I4: 400 | K4: 1 | L4: 0 | M4: 0 | N4: 0 | O4: 0 | P4: 1 | Q4: 1 | R4: 0 | S4: =A5-A4 -> 0.2 | T4: =C4+Summary!$C$8*D4 -> 0.112378 | U4: =B4*T4 -> 1.3455018 | V4: =B4*C4 -> -4.130685
A5: 175.44 | B5: 11.977 | C5: -0.346 | D5: 5.629 | E5: 0 | F5: 76 | G5: 400 | H5: 124 | I5: 400 | K5: 1 | L5: 0 | M5: 0 | N5: 0 | O5: 0 | P5: 1 | Q5: 1 | R5: 0 | S5: =A6-A5 -> 0.19 | T5: =C5+Summary!$C$8*D5 -> 0.1127635 | U5: =B5*T5 -> 1.3505684 | V5: =B5*C5 -> -4.144042
A6: 175.63 | B6: 11.977 | C6: -0.348 | D6: 5.635 | E6: 0 | F6: 76 | G6: 400 | H6: 126 | I6: 400 | K6: 1 | L6: 0 | M6: 0 | N6: 0 | O6: 0 | P6: 1 | Q6: 1 | R6: 0 | S6: =A7-A6 -> 0.21 | T6: =C6+Summary!$C$8*D6 -> 0.1112525 | U6: =B6*T6 -> 1.3324712 | V6: =B6*C6 -> -4.167996
A7: 175.84 | B7: 11.98 | C7: -0.347 | D7: 5.641 | E7: 0 | F7: 76 | G7: 72 | H7: 29 | I7: 400 | K7: 1 | L7: 0 | M7: 0 | N7: 0 | O7: 0 | P7: 1 | Q7: 1 | R7: 0 | S7: =A8-A7 -> 0.19 | T7: =C7+Summary!$C$8*D7 -> 0.1127415 | U7: =B7*T7 -> 1.3506432 | V7: =B7*C7 -> -4.15706
A8: 176.03 | B8: 11.976 | C8: -0.313 | D8: 5.647 | E8: 0 | F8: 76 | G8: 400 | H8: 126 | I8: 400 | K8: 1 | L8: 0 | M8: 0 | N8: 0 | O8: 0 | P8: 1 | Q8: 1 | R8: 0 | S8: =A9-A8 -> 0.21 | T8: =C8+Summary!$C$8*D8 -> 0.1472305 | U8: =B8*T8 -> 1.7632325 | V8: =B8*C8 -> -3.748488
A9: 176.24 | B9: 11.98 | C9: -0.35 | D9: 5.681 | E9: 0 | F9: 76 | G9: 73 | H9: 29 | I9: 400 | K9: 1 | L9: 0 | M9: 0 | N9: 0 | O9: 0 | P9: 1 | Q9: 1 | R9: 0 | S9: =A10-A9 -> 0.2 | T9: =C9+Summary!$C$8*D9 -> 0.1130015 | U9: =B9*T9 -> 1.353758 | V9: =B9*C9 -> -4.193
A10: 176.44 | B10: 11.98 | C10: -0.353 | D10: 5.694 | E10: 0 | F10: 76 | G10: 72 | H10: 30 | I10: 400 | K10: 1 | L10: 0 | M10: 0 | N10: 0 | O10: 0 | P10: 1 | Q10: 1 | R10: 0 | S10: =A11-A10 -> 0.19 | T10: =C10+Summary!$C$8*D10 -> 0.111061 | U10: =B10*T10 -> 1.3305108 | V10: =B10*C10 -> -4.22894
A11: 176.63 | B11: 11.98 | C11: -0.352 | D11: 5.713 | E11: 0 | F11: 76 | G11: 400 | H11: 126 | I11: 400 | K11: 1 | L11: 0 | M11: 0 | N11: 0 | O11: 0 | P11: 1 | Q11: 1 | R11: 0 | S11: =A12-A11 -> 0.21 | T11: =C11+Summary!$C$8*D11 -> 0.1136095 | U11: =B11*T11 -> 1.3610418 | V11: =B11*C11 -> -4.21696
A12: 176.84 | B12: 11.98 | C12: -0.355 | D12: 5.737 | E12: 0 | F12: 76 | G12: 400 | H12: 124 | I12: 400 | K12: 1 | L12: 0 | M12: 0 | N12: 0 | O12: 0 | P12: 1 | Q12: 1 | R12: 0 | S12: =A13-A12 -> 0.19 | T12: =C12+Summary!$C$8*D12 -> 0.1125655 | U12: =B12*T12 -> 1.3485347 | V12: =B12*C12 -> -4.2529
A13: 177.03 | B13: 11.984 | C13: -0.357 | D13: 5.763 | E13: 0 | F13: 76 | G13: 400 | H13: 29 | I13: 400 | K13: 1 | L13: 0 | M13: 0 | N13: 0 | O13: 0 | P13: 1 | Q13: 1 | R13: 0 | S13: =A14-A13 -> 0.21 | T13: =C13+Summary!$C$8*D13 -> 0.1126845 | U13: =B13*T13 -> 1.350411 | V13: =B13*C13 -> -4.278288
... A35: 181.44 | B35: 11.984 | C35: -0.354 | D35: 5.721 | E35: 0 | F35: 76 | G35: 400 | H35: 37 | I35: 400 | K35: 1 | L35: 0 | M35: 0 | N35: 0 | O35: 0 | P35: 1 | Q35: 1 | R35: 0 | S35: =A36-A35 -> 0.2 | T35: =C35+Summary!$C$8*D35 -> 0.1122615 | U35: =B35*T35 -> 1.3453418 | V35: =B35*C35 -> -4.242336
A36: 181.64 | B36: 11.951 | C36: -0.249 | D36: 5.71 | E36: 0 | F36: 76 | G36: 400 | H36: 124 | I36: 400 | K36: 1 | L36: 1 | M36: 0 | N36: 0 | O36: 0 | P36: 1 | Q36: 1 | R36: 0 | S36: =A37-A36 -> 0.2 | T36: =C36+Summary!$C$8*D36 -> 0.216365 | U36: =B36*T36 -> 2.5857781 | V36: =B36*C36 -> -2.975799 | W36: Sun 1 | X36: Sun
A37: 181.84 | B37: 11.819 | C37: 0.165 | D37: 5.657 | E37: 0 | F37: 76 | G37: 400 | H37: 29 | I37: 400 | K37: 1 | L37: 1 | M37: 0 | N37: 0 | O37: 0 | P37: 1 | Q37: 1 | R37: 0 | S37: =A38-A37 -> 0.2 | T37: =C37+Summary!$C$8*D37 -> 0.6260455 | U37: =B37*T37 -> 7.3992318 | V37: =B37*C37 -> 1.950135 | W37: Sun 1 | X37: Sun
A38: 182.04 | B38: 11.819 | C38: 0.105 | D38: 5.646 | E38: 0 | F38: 76 | G38: 400 | H38: 122 | I38: 28 | K38: 1 | L38: 1 | M38: 0 | N38: 0 | O38: 0 | P38: 1 | Q38: 1 | R38: 0 | S38: =A39-A38 -> 0.2 | T38: =C38+Summary!$C$8*D38 -> 0.565149 | U38: =B38*T38 -> 6.679496 | V38: =B38*C38 -> 1.240995 | W38: Sun 1 | X38: Sun
A39: 182.24 | B39: 11.879 | C39: -0.051 | D39: 5.654 | E39: 0 | F39: 76 | G39: 400 | H39: 69 | I39: 400 | K39: 1 | L39: 1 | M39: 0 | N39: 0 | O39: 0 | P39: 1 | Q39: 1 | R39: 0 | S39: =A40-A39 -> 0.2 | T39: =C39+Summary!$C$8*D39 -> 0.409801 | U39: =B39*T39 -> 4.8680261 | V39: =B39*C39 -> -0.605829 | W39: Sun 1 | X39: Sun
A40: 182.44 | B40: 11.91 | C40: -0.154 | D40: 5.615 | E40: 0.095 | F40: 76 | G40: 400 | H40: 17 | I40: 400 | K40: 1 | L40: 1 | M40: 0 | N40: 0 | O40: 0 | P40: 1 | Q40: 1 | R40: 0 | S40: =A41-A40 -> 0.2 | T40: =C40+Summary!$C$8*D40 -> 0.3036225 | U40: =B40*T40 -> 3.616144 | V40: =B40*C40 -> -1.83414 | W40: Sun 1 | X40: Sun
A41: 182.64 | B41: 11.844 | C41: 0.063 | D41: 5.535 | E41: 0.136 | F41: 76 | G41: 400 | H41: 108 | I41: 400 | K41: 1 | L41: 1 | M41: 0 | N41: 0 | O41: 0 | P41: 1 | Q41: 1 | R41: 0 | S41: =A42-A41 -> 0.2 | T41: =C41+Summary!$C$8*D41 -> 0.5141025 | U41: =B41*T41 -> 6.08903 | V41: =B41*C41 -> 0.746172 | W41: Sun 1 | X41: Sun
A42: 182.84 | B42: 11.851 | C42: 0.059 | D42: 5.523 | E42: 0.027 | F42: 76 | G42: 400 | H42: 45 | I42: 18 | K42: 1 | L42: 1 | M42: 0 | N42: 0 | O42: 0 | P42: 1 | Q42: 1 | R42: 0 | S42: =A43-A42 -> 0.2 | T42: =C42+Summary!$C$8*D42 -> 0.5091245 | U42: =B42*T42 -> 6.0336344 | V42: =B42*C42 -> 0.699209 | W42: Sun 1 | X42: Sun
A43: 183.04 | B43: 11.836 | C43: 0.08 | D43: 5.479 | E43: 0.027 | F43: 76 | G43: 22 | H43: 26 | I43: 18 | K43: 1 | L43: 1 | M43: 0 | N43: 0 | O43: 0 | P43: 1 | Q43: 1 | R43: 0 | S43: =A44-A43 -> 0.2 | T43: =C43+Summary!$C$8*D43 -> 0.5265385 | U43: =B43*T43 -> 6.2321097 | V43: =B43*C43 -> 0.94688 | W43: Sun 1 | X43: Sun
A44: 183.24 | B44: 11.854 | C44: 0.027 | D44: 5.511 | E44: 0 | F44: 76 | G44: 400 | H44: 27 | I44: 400 | K44: 1 | L44: 1 | M44: 0 | N44: 0 | O44: 0 | P44: 1 | Q44: 1 | R44: 0 | S44: =A45-A44 -> 0.2 | T44: =C44+Summary!$C$8*D44 -> 0.4761465 | U44: =B44*T44 -> 5.6442406 | V44: =B44*C44 -> 0.320058 | W44: Sun 1 | X44: Sun
A45: 183.44 | B45: 11.854 | C45: -0.017 | D45: 5.483 | E45: 0 | F45: 76 | G45: 400 | H45: 22 | I45: 400 | K45: 1 | L45: 1 | M45: 0 | N45: 0 | O45: 0 | P45: 1 | Q45: 1 | R45: 0 | S45: =A46-A45 -> 0.2 | T45: =C45+Summary!$C$8*D45 -> 0.4298645 | U45: =B45*T45 -> 5.0956138 | V45: =B45*C45 -> -0.201518 | W45: Sun 1 | X45: Sun
A46: 183.64 | B46: 11.845 | C46: -0.014 | D46: 5.464 | E46: 0.027 | F46: 76 | G46: 400 | H46: 400 | I46: 400 | K46: 1 | L46: 1 | M46: 0 | N46: 0 | O46: 0 | P46: 1 | Q46: 1 | R46: 0 | S46: =A47-A46 -> 0.2 | T46: =C46+Summary!$C$8*D46 -> 0.431316 | U46: =B46*T46 -> 5.108938 | V46: =B46*C46 -> -0.16583 | W46: Sun 1 | X46: Sun
A47: 183.84 | B47: 11.899 | C47: -0.103 | D47: 5.544 | E47: 0 | F47: 76 | G47: 400 | H47: 400 | I47: 400 | K47: 1 | L47: 1 | M47: 0 | N47: 0 | O47: 0 | P47: 1 | Q47: 1 | R47: 0 | S47: =A48-A47 -> 0.19 | T47: =C47+Summary!$C$8*D47 -> 0.348836 | U47: =B47*T47 -> 4.1507996 | V47: =B47*C47 -> -1.225597 | W47: Sun 1 | X47: Sun
... A76: 189.64 | B76: 11.948 | C76: -0.273 | D76: 4.729 | E76: 0 | F76: 76 | G76: 400 | H76: 400 | I76: 400 | K76: 1 | L76: 0 | M76: 0 | N76: 0 | O76: 0 | P76: 1 | Q76: 1 | R76: 0 | S76: =A77-A76 -> 0.2 | T76: =C76+Summary!$C$8*D76 -> 0.1124135 | U76: =B76*T76 -> 1.3431165 | V76: =B76*C76 -> -3.261804 | W76: Sun 1 | X76: Sun
A77: 189.84 | B77: 11.948 | C77: -0.272 | D77: 4.693 | E77: 0 | F77: 76 | G77: 400 | H77: 400 | I77: 400 | K77: 1 | L77: 0 | M77: 0 | N77: 0 | O77: 0 | P77: 1 | Q77: 1 | R77: 0 | S77: =A78-A77 -> 0.2 | T77: =C77+Summary!$C$8*D77 -> 0.1104795 | U77: =B77*T77 -> 1.3200091 | V77: =B77*C77 -> -3.249856
A78: 190.04 | B78: 11.952 | C78: -0.267 | D78: 4.684 | E78: 0 | F78: 76 | G78: 400 | H78: 400 | I78: 400 | K78: 1 | L78: 0 | M78: 0 | N78: 0 | O78: 0 | P78: 1 | Q78: 1 | R78: 0 | S78: =A79-A78 -> 0.2 | T78: =C78+Summary!$C$8*D78 -> 0.114746 | U78: =B78*T78 -> 1.3714442 | V78: =B78*C78 -> -3.191184
A79: 190.24 | B79: 11.903 | C79: -0.123 | D79: 4.66 | E79: 0 | F79: 76 | G79: 400 | H79: 400 | I79: 400 | K79: 1 | L79: 1 | M79: 0 | N79: 0 | O79: 0 | P79: 1 | Q79: 1 | R79: 0 | S79: =A80-A79 -> 0.2 | T79: =C79+Summary!$C$8*D79 -> 0.25679 | U79: =B79*T79 -> 3.0565714 | V79: =B79*C79 -> -1.464069 | W79: Sun 2 | X79: Sun
A80: 190.44 | B80: 11.698 | C80: 0.621 | D80: 4.551 | E80: 0 | F80: 76 | G80: 400 | H80: 400 | I80: 40 | K80: 1 | L80: 1 | M80: 0 | N80: 0 | O80: 0 | P80: 1 | Q80: 1 | R80: 0 | S80: =A81-A80 -> 0.2 | T80: =C80+Summary!$C$8*D80 -> 0.9919065 | U80: =B80*T80 -> 11.603322 | V80: =B80*C80 -> 7.264458 | W80: Sun 2 | X80: Sun
A81: 190.64 | B81: 11.661 | C81: 0.643 | D81: 4.542 | E81: 0.108 | F81: 76 | G81: 400 | H81: 23 | I81: 37 | K81: 1 | L81: 1 | M81: 0 | N81: 0 | O81: 0 | P81: 1 | Q81: 1 | R81: 0 | S81: =A82-A81 -> 0.2 | T81: =C81+Summary!$C$8*D81 -> 1.013173 | U81: =B81*T81 -> 11.81461 | V81: =B81*C81 -> 7.498023 | W81: Sun 2 | X81: Sun
A82: 190.84 | B82: 11.755 | C82: 0.276 | D82: 4.434 | E82: 0.217 | F82: 76 | G82: 400 | H82: 400 | I82: 400 | K82: 1 | L82: 1 | M82: 0 | N82: 0 | O82: 0 | P82: 1 | Q82: 1 | R82: 0 | S82: =A83-A82 -> 0.2 | T82: =C82+Summary!$C$8*D82 -> 0.637371 | U82: =B82*T82 -> 7.4922961 | V82: =B82*C82 -> 3.24438 | W82: Sun 2 | X82: Sun
A83: 191.04 | B83: 11.821 | C83: 0.154 | D83: 4.387 | E83: 0.217 | F83: 76 | G83: 400 | H83: 400 | I83: 400 | K83: 1 | L83: 1 | M83: 0 | N83: 0 | O83: 0 | P83: 1 | Q83: 1 | R83: 0 | S83: =A84-A83 -> 0.2 | T83: =C83+Summary!$C$8*D83 -> 0.5115405 | U83: =B83*T83 -> 6.0469203 | V83: =B83*C83 -> 1.820434 | W83: Sun 2 | X83: Sun
A84: 191.24 | B84: 11.773 | C84: 0.184 | D84: 4.165 | E84: 0.231 | F84: 76 | G84: 400 | H84: 27 | I84: 400 | K84: 1 | L84: 1 | M84: 0 | N84: 0 | O84: 0 | P84: 1 | Q84: 1 | R84: 0 | S84: =A85-A84 -> 0.2 | T84: =C84+Summary!$C$8*D84 -> 0.5234475 | U84: =B84*T84 -> 6.1625474 | V84: =B84*C84 -> 2.166232 | W84: Sun 2 | X84: Sun
A85: 191.44 | B85: 11.84 | C85: 0.085 | D85: 4.157 | E85: 0.19 | F85: 76 | G85: 400 | H85: 21 | I85: 20 | K85: 1 | L85: 1 | M85: 0 | N85: 0 | O85: 0 | P85: 1 | Q85: 1 | R85: 0 | S85: =A86-A85 -> 0.2 | T85: =C85+Summary!$C$8*D85 -> 0.4237955 | U85: =B85*T85 -> 5.0177387 | V85: =B85*C85 -> 1.0064 | W85: Sun 2 | X85: Sun
A86: 191.64 | B86: 11.821 | C86: 0.152 | D86: 4.237 | E86: 0.149 | F86: 76 | G86: 400 | H86: 400 | I86: 400 | K86: 1 | L86: 1 | M86: 0 | N86: 0 | O86: 0 | P86: 1 | Q86: 1 | R86: 0 | S86: =A87-A86 -> 0.2 | T86: =C86+Summary!$C$8*D86 -> 0.4973155 | U86: =B86*T86 -> 5.8787665 | V86: =B86*C86 -> 1.796792 | W86: Sun 2 | X86: Sun
A87: 191.84 | B87: 11.798 | C87: 0.134 | D87: 4.296 | E87: 0.163 | F87: 76 | G87: 400 | H87: 30 | I87: 400 | K87: 1 | L87: 1 | M87: 0 | N87: 0 | O87: 0 | P87: 1 | Q87: 1 | R87: 0 | S87: =A88-A87 -> 0.2 | T87: =C87+Summary!$C$8*D87 -> 0.484124 | U87: =B87*T87 -> 5.711695 | V87: =B87*C87 -> 1.580932 | W87: Sun 2 | X87: Sun
A88: 192.04 | B88: 11.808 | C88: 0.149 | D88: 4.372 | E88: 0.163 | F88: 76 | G88: 400 | H88: 400 | I88: 35 | K88: 1 | L88: 1 | M88: 0 | N88: 0 | O88: 0 | P88: 1 | Q88: 1 | R88: 0 | S88: =A89-A88 -> 0.2 | T88: =C88+Summary!$C$8*D88 -> 0.505318 | U88: =B88*T88 -> 5.9667949 | V88: =B88*C88 -> 1.759392 | W88: Sun 2 | X88: Sun
A89: 192.24 | B89: 11.795 | C89: 0.181 | D89: 4.326 | E89: 0.163 | F89: 76 | G89: 400 | H89: 59 | I89: 400 | K89: 1 | L89: 1 | M89: 0 | N89: 0 | O89: 0 | P89: 1 | Q89: 1 | R89: 0 | S89: =A90-A89 -> 0.2 | T89: =C89+Summary!$C$8*D89 -> 0.533569 | U89: =B89*T89 -> 6.2934464 | V89: =B89*C89 -> 2.134895 | W89: Sun 2 | X89: Sun
...

Sheet Profiles
A1: Sun 1 | G1: Sun 2 | M1: Sun 3 | S1: Sun 4 | Y1: Sun 5 | AE1: Sun 6 | AK1: Sun 7 | AQ1: Shade 1 | AW1: Shade 2 | BC1: Shade 3 | BI1: Shade 4 | BO1: Charge 1 | BT1: Charge 2
A2: t since start (s) | B2: speed (m/s) | C2: load power (W) | D2: battery power (W) | E2: PV power (W) | G2: t since start (s) | H2: speed (m/s) | I2: load power (W) | J2: battery power (W) | K2: PV power (W) | M2: t since start (s) | N2: speed (m/s) | O2: load power (W) | P2: battery power (W) | Q2: PV power (W) | S2: t since start (s) | T2: speed (m/s) | U2: load power (W) | V2: battery power (W) | W2: PV power (W) | Y2: t since start (s) | Z2: speed (m/s) | AA2: load power (W) | AB2: battery power (W) | AC2: PV power (W) | AE2: t since start (s) | AF2: speed (m/s) | AG2: load power (W) | AH2: battery power (W) | AI2: PV power (W) | AK2: t since start (s) | AL2: speed (m/s) | AM2: load power (W) | AN2: battery power (W) | AO2: PV power (W) | AQ2: t since start (s) | AR2: speed (m/s) | AS2: load power (W) | AT2: battery power (W) | AU2: PV power (W) | AW2: t since start (s) | AX2: speed (m/s) | AY2: load power (W) | AZ2: battery power (W) | BA2: PV power (W) | BC2: t since start (s) | BD2: speed (m/s) | BE2: load power (W) | BF2: battery power (W) | BG2: PV power (W) | BI2: t since start (s) | BJ2: speed (m/s) | BK2: load power (W) | BL2: battery power (W) | BM2: PV power (W) | BO2: t since start (s) | BP2: PV power (W) | BQ2: electronics load (W) | BR2: into battery (W) | BT2: t since start (s) | BU2: PV power (W) | BV2: electronics load (W) | BW2: into battery (W)
A3: 0 | B3: 0 | C3: 2.586 | D3: -2.976 | E3: 5.71 | G3: 0 | H3: 0 | I3: 3.057 | J3: -1.464 | K3: 4.66 | M3: 0 | N3: 0 | O3: 1.316 | P3: -2.553 | Q3: 3.979 | S3: 0 | T3: 0 | U3: 1.335 | V3: -3.853 | W3: 5.32 | Y3: 0 | Z3: 0 | AA3: 2.539 | AB3: -2.146 | AC3: 4.822 | AE3: 0 | AF3: 0.013 | AG3: 15.059 | AH3: 11.353 | AI3: 3.945 | AK3: 0 | AL3: 0 | AM3: 8.014 | AN3: 4.814 | AO3: 3.351 | AQ3: 0 | AR3: 0 | AS3: 1.328 | AT3: 1.205 | AU3: 0.128 | AW3: 0 | AX3: 0.013 | AY3: 8.213 | AZ3: 7.571 | BA3: 0.677 | BC3: 0 | BD3: 0.027 | BE3: 9.223 | BF3: 9.069 | BG3: 0.163 | BI3: 0 | BJ3: 0 | BK3: 3.397 | BL3: 3.354 | BM3: 0.045 | BO3: 0 | BP3: 5.611 | BQ3: 1.345 | BR3: 4.132 | BT3: 0 | BU3: 3.925 | BV3: 1.322 | BW3: 2.493
A4: 0.2 | B4: 0 | C4: 7.399 | D4: 1.95 | E4: 5.657 | G4: 0.2 | H4: 0 | I4: 11.603 | J4: 7.264 | K4: 4.551 | M4: 0.2 | N4: 0 | O4: 2.718 | P4: -1.118 | Q4: 3.958 | S4: 0.2 | T4: 0 | U4: 6.326 | V4: 1.197 | W4: 5.312 | Y4: 0.19 | Z4: 0 | AA4: 14.512 | AB4: 10.129 | AC4: 4.656 | AE4: 0.2 | AF4: 0.013 | AG4: 9.207 | AH4: 5.554 | AI4: 3.834 | AK4: 0.2 | AL4: 0 | AM4: 10.871 | AN4: 7.852 | AO4: 3.189 | AQ4: 0.2 | AR4: 0 | AS4: 3.719 | AT4: 3.594 | AU4: 0.13 | AW4: 0.2 | AX4: 0.013 | AY4: 11.498 | AZ4: 10.716 | BA4: 0.834 | BC4: 0.2 | BD4: 0.027 | BE4: 11.021 | BF4: 10.811 | BG4: 0.224 | BI4: 0.18 | BJ4: 0.013 | BK4: 12.779 | BL4: 12.731 | BM4: 0.051 | BO4: 0.19 | BP4: 5.605 | BQ4: 1.339 | BR4: 4.132 | BT4: 0.2 | BU4: 3.933 | BV4: 1.318 | BW4: 2.504
A5: 0.4 | B5: 0 | C5: 6.679 | D5: 1.241 | E5: 5.646 | G5: 0.4 | H5: 0.108 | I5: 11.815 | J5: 7.498 | K5: 4.542 | M5: 0.4 | N5: 0 | O5: 2.977 | P5: -0.843 | Q5: 3.946 | S5: 0.4 | T5: 0 | U5: 5.06 | V5: -0.107 | W5: 5.338 | Y5: 0.39 | Z5: 0.122 | AA5: 8.026 | AB5: 3.672 | AC5: 4.539 | AE5: 0.4 | AF5: 0.258 | AG5: 7.191 | AH5: 3.517 | AI5: 3.833 | AK5: 0.4 | AL5: 0.149 | AM5: 7.704 | AN5: 4.647 | AO5: 3.196 | AQ5: 0.41 | AR5: 0.013 | AS5: 4.672 | AT5: 4.548 | AU5: 0.13 | AW5: 0.4 | AX5: 0.122 | AY5: 8.278 | AZ5: 5.394 | BA5: 3.037 | BC5: 0.4 | BD5: 0.231 | BE5: 6.557 | BF5: 6.29 | BG5: 0.282 | BI5: 0.38 | BJ5: 0.353 | BK5: 8.584 | BL5: 8.542 | BM5: 0.045 | BO5: 0.4 | BP5: 5.612 | BQ5: 1.346 | BR5: 4.131 | BT5: 0.4 | BU5: 3.908 | BV5: 1.746 | BW5: 2.05
A6: 0.6 | B6: 0 | C6: 4.868 | D6: -0.606 | E6: 5.654 | G6: 0.6 | H6: 0.217 | I6: 7.492 | J6: 3.244 | K6: 4.434 | M6: 0.6 | N6: 0 | O6: 7.711 | P6: 3.962 | Q6: 3.913 | S6: 0.6 | T6: 0 | U6: 5.012 | V6: -0.154 | W6: 5.34 | Y6: 0.59 | Z6: 0.217 | AA6: 6.951 | AB6: 2.592 | AC6: 4.539 | AE6: 0.6 | AF6: 0.231 | AG6: 5.853 | AH6: 2.099 | AI6: 3.906 | AK6: 0.6 | AL6: 0.285 | AM6: 5.893 | AN6: 2.85 | AO6: 3.171 | AQ6: 0.61 | AR6: 0 | AS6: 5.284 | AT6: 5.159 | AU6: 0.131 | AW6: 0.6 | AX6: 0.299 | AY6: 7.789 | AZ6: 5.341 | BA6: 2.576 | BC6: 0.6 | BD6: 0.503 | BE6: 6.154 | BF6: 6.008 | BG6: 0.154 | BI6: 0.59 | BJ6: 0.598 | BK6: 6.764 | BL6: 6.717 | BM6: 0.05 | BO6: 0.6 | BP6: 5.629 | BQ6: 1.351 | BR6: 4.144 | BT6: 0.6 | BU6: 3.949 | BV6: 1.31 | BW6: 2.528
A7: 0.8 | B7: 0.095 | C7: 3.616 | D7: -1.834 | E7: 5.615 | G7: 0.8 | H7: 0.217 | I7: 6.047 | J7: 1.82 | K7: 4.387 | M7: 0.8 | N7: 0 | O7: 6.498 | P7: 2.579 | Q7: 4.084 | S7: 0.8 | T7: 0 | U7: 10.742 | V7: 5.74 | W7: 5.24 | Y7: 0.79 | Z7: 0.217 | AA7: 5.509 | AB7: 1.134 | AC7: 4.544 | AE7: 0.8 | AF7: 0.258 | AG7: 5.642 | AH7: 2.086 | AI7: 3.701 | AK7: 0.8 | AL7: 0.34 | AM7: 6.158 | AN7: 3.193 | AO7: 3.088 | AQ7: 0.81 | AR7: 0.095 | AS7: 6.398 | AT7: 6.283 | AU7: 0.121 | AW7: 0.8 | AX7: 0.394 | AY7: 6.432 | AZ7: 4.382 | BA7: 2.147 | BC7: 0.8 | BD7: 0.694 | BE7: 6.253 | BF7: 6.132 | BG7: 0.127 | BI7: 0.78 | BJ7: 0.598 | BK7: 6.501 | BL7: 6.454 | BM7: 0.05 | BO7: 0.79 | BP7: 5.635 | BQ7: 1.332 | BR7: 4.168 | BT7: 0.8 | BU7: 3.97 | BV7: 1.318 | BW7: 2.54
A8: 1 | B8: 0.136 | C8: 6.089 | D8: 0.746 | E8: 5.535 | G8: 1 | H8: 0.231 | I8: 6.163 | J8: 2.166 | K8: 4.165 | M8: 1 | N8: 0.068 | O8: 6.602 | P8: 2.651 | Q8: 4.113 | S8: 1 | T8: 0 | U8: 6.822 | V8: 1.82 | W8: 5.195 | Y8: 0.99 | Z8: 0.19 | AA8: 6.12 | AB8: 2.02 | AC8: 4.26 | AE8: 1 | AF8: 0.326 | AG8: 5.914 | AH8: 2.412 | AI8: 3.652 | AK8: 1 | AL8: 0.353 | AM8: 5.968 | AN8: 3.4 | AO8: 2.679 | AQ8: 1.02 | AR8: 0.095 | AS8: 9.969 | AT8: 9.857 | AU8: 0.118 | AW8: 1 | AX8: 0.408 | AY8: 6.938 | AZ8: 6.774 | BA8: 0.172 | BC8: 1 | BD8: 0.68 | BE8: 7.501 | BF8: 7.375 | BG8: 0.133 | BI8: 0.98 | BJ8: 0.694 | BK8: 5.754 | BL8: 5.71 | BM8: 0.047 | BO8: 1 | BP8: 5.641 | BQ8: 1.351 | BR8: 4.157 | BT8: 1 | BU8: 4.018 | BV8: 1.317 | BW8: 2.588
A9: 1.2 | B9: 0.027 | C9: 6.034 | D9: 0.699 | E9: 5.523 | G9: 1.2 | H9: 0.19 | I9: 5.018 | J9: 1.006 | K9: 4.157 | M9: 1.2 | N9: 0.068 | O9: 8.392 | P9: 4.448 | Q9: 4.123 | S9: 1.2 | T9: 0 | U9: 5.965 | V9: 0.947 | W9: 5.203 | Y9: 1.19 | Z9: 0.176 | AA9: 6.319 | AB9: 2.229 | AC9: 4.254 | AE9: 1.2 | AF9: 0.326 | AG9: 5.849 | AH9: 2.319 | AI9: 3.679 | AK9: 1.2 | AL9: 0.353 | AM9: 5.769 | AN9: 4.137 | AO9: 1.703 | AQ9: 1.22 | AR9: 0.204 | AS9: 6.589 | AT9: 6.461 | AU9: 0.135 | AW9: 1.2 | AX9: 0.408 | AY9: 6.434 | AZ9: 6.251 | BA9: 0.193 | BC9: 1.2 | BD9: 0.68 | BE9: 7.147 | BF9: 7.005 | BG9: 0.149 | BI9: 1.18 | BJ9: 0.68 | BK9: 7.042 | BL9: 7.006 | BM9: 0.038 | BO9: 1.19 | BP9: 5.647 | BQ9: 1.763 | BR9: 3.748 | BT9: 1.2 | BU9: 4.057 | BV9: 1.308 | BW9: 2.636
A10: 1.4 | B10: 0.027 | C10: 6.232 | D10: 0.947 | E10: 5.479 | G10: 1.4 | H10: 0.149 | I10: 5.879 | J10: 1.797 | K10: 4.237 | M10: 1.4 | N10: 0.136 | O10: 7.436 | P10: 3.365 | Q10: 4.245 | S10: 1.4 | T10: 0.013 | U10: 6.045 | V10: 1.1 | W10: 5.128 | Y10: 1.39 | Z10: 0.19 | AA10: 5.574 | AB10: 1.464 | AC10: 4.273 | AE10: 1.4 | AF10: 0.299 | AG10: 2.306 | AH10: -1.093 | AI10: 3.511 | AK10: 1.4 | AL10: 0.353 | AM10: 1.84 | AN10: 0.32 | AO10: 1.575 | AQ10: 1.42 | AR10: 0.585 | AS10: 6.665 | AT10: 6.523 | AU10: 0.149 | AW10: 1.4 | AX10: 0.707 | AY10: 5.956 | AZ10: 5.824 | BA10: 0.138 | BC10: 1.4 | BD10: 0.544 | BE10: 6.41 | BF10: 6.3 | BG10: 0.117 | BI10: 1.38 | BJ10: 0.653 | BK10: 6.601 | BL10: 6.558 | BM10: 0.045 | BO10: 1.4 | BP10: 5.681 | BQ10: 1.354 | BR10: 4.193 | BT10: 1.4 | BU10: 4.107 | BV10: 1.321 | BW10: 2.673
A11: 1.6 | B11: 0 | C11: 5.644 | D11: 0.32 | E11: 5.511 | G11: 1.6 | H11: 0.163 | I11: 5.712 | J11: 1.581 | K11: 4.296 | M11: 1.6 | N11: 0.136 | O11: 7.04 | P11: 3 | Q11: 4.215 | S11: 1.6 | T11: 0 | U11: 5.961 | V11: 1.005 | W11: 5.142 | Y11: 1.59 | Z11: 0.19 | AA11: 2.207 | AB11: -1.918 | AC11: 4.249 | AE11: 1.6 | AF11: 0.258 | AG11: 2.109 | AH11: -1.26 | AI11: 3.477 | AK11: 1.6 | AL11: 0.326 | AM11: 1.315 | AN11: -0.036 | AO11: 1.398 | AQ11: 1.62 | AR11: 0.68 | AS11: 5.704 | AT11: 5.521 | AU11: 0.192 | AW11: 1.6 | AX11: 0.694 | AY11: 5.671 | AZ11: 5.614 | BA11: 0.06 | BC11: 1.6 | BD11: 0.68 | BE11: 6.857 | BF11: 6.788 | BG11: 0.073 | BI11: 1.58 | BJ11: 0.694 | BK11: 6.43 | BL11: 6.384 | BM11: 0.048 | BO11: 1.6 | BP11: 5.694 | BQ11: 1.331 | BR11: 4.229 | BT11: 1.6 | BU11: 4.165 | BV11: 1.318 | BW11: 2.732
A12: 1.8 | B12: 0 | C12: 5.096 | D12: -0.202 | E12: 5.483 | G12: 1.8 | H12: 0.163 | I12: 5.967 | J12: 1.759 | K12: 4.372 | M12: 1.8 | N12: 0.122 | O12: 2.452 | P12: -1.619 | Q12: 4.197 | S12: 1.8 | T12: 0 | U12: 5.887 | V12: 0.934 | W12: 5.142 | Y12: 1.79 | Z12: 0.19 | AA12: 1.413 | AB12: -2.685 | AC12: 4.213 | AE12: 1.8 | AF12: 0.19 | AG12: 1.33 | AH12: -1.989 | AI12: 3.419 | AK12: 1.8 | AL12: 0.163 | AM12: 1.307 | AN12: -0.368 | AO12: 1.733 | AQ12: 1.82 | AR12: 0.517 | AS12: 6.633 | AT12: 6.437 | AU12: 0.206 | AW12: 1.8 | AX12: 0.735 | AY12: 5.636 | AZ12: 5.593 | BA12: 0.045 | BC12: 1.8 | BD12: 0.694 | BE12: 7.048 | BF12: 6.913 | BG12: 0.142 | BI12: 1.79 | BJ12: 0.694 | BK12: 6.509 | BL12: 6.485 | BM12: 0.026 | BO12: 1.79 | BP12: 5.713 | BQ12: 1.361 | BR12: 4.217 | BT12: 1.8 | BU12: 4.223 | BV12: 1.314 | BW12: 2.791
A13: 2 | B13: 0.027 | C13: 5.109 | D13: -0.166 | E13: 5.464 | G13: 2 | H13: 0.163 | I13: 6.293 | J13: 2.135 | K13: 4.326 | M13: 2 | N13: 0.108 | O13: 2.596 | P13: -1.403 | Q13: 4.126 | S13: 2 | T13: 0.013 | U13: 5.923 | V13: 1.064 | W13: 5.046 | Y13: 1.99 | Z13: 0.149 | AA13: 1.309 | AB13: -2.78 | AC13: 4.205 | AE13: 2 | AF13: 0.068 | AG13: 1.305 | AH13: -1.977 | AI13: 3.381 | AK13: 2 | AL13: 0.068 | AM13: 1.302 | AN13: -0.57 | AO13: 1.935 | AQ13: 2.02 | AR13: 0.517 | AS13: 5.973 | AT13: 5.773 | AU13: 0.211 | AW13: 2 | AX13: 0.735 | AY13: 5.399 | AZ13: 5.32 | BA13: 0.083 | BC13: 2 | BD13: 0.694 | BE13: 6.246 | BF13: 6.125 | BG13: 0.127 | BI13: 1.99 | BJ13: 0.694 | BK13: 7.257 | BL13: 7.232 | BM13: 0.026 | BO13: 2 | BP13: 5.737 | BQ13: 1.349 | BR13: 4.253 | BT13: 2 | BU13: 4.261 | BV13: 1.316 | BW13: 2.828
A14: 2.2 | B14: 0 | C14: 4.151 | D14: -1.226 | E14: 5.544 | G14: 2.2 | H14: 0.095 | I14: 10.032 | J14: 5.925 | K14: 4.303 | M14: 2.2 | N14: 0.108 | O14: 2.82 | P14: -1.118 | Q14: 4.063 | S14: 2.2 | T14: 0.027 | U14: 5.735 | V14: 0.944 | W14: 4.979 | Y14: 2.19 | Z14: 0.027 | AA14: 1.324 | AB14: -2.72 | AC14: 4.159 | AE14: 2.2 | AF14: 0.068 | AG14: 1.302 | AH14: -1.953 | AI14: 3.354 | AK14: 2.2 | AL14: 0.068 | AM14: 1.293 | AN14: -0.273 | AO14: 1.62 | AQ14: 2.22 | AR14: 0.667 | AS14: 6.354 | AT14: 6.118 | AU14: 0.248 | AW14: 2.2 | AX14: 0.735 | AY14: 5.578 | AZ14: 5.432 | BA14: 0.153 | BC14: 2.2 | BD14: 0.694 | BE14: 6.178 | BF14: 6.069 | BG14: 0.115 | BI14: 2.19 | BJ14: 0.68 | BK14: 6.163 | BL14: 6.141 | BM14: 0.024 | BO14: 2.19 | BP14: 5.763 | BQ14: 1.35 | BR14: 4.278 | BT14: 2.2 | BU14: 4.269 | BV14: 1.372 | BW14: 2.781
A15: 2.39 | B15: 0 | C15: 6.893 | D15: 1.575 | E15: 5.511 | G15: 2.4 | H15: 0.245 | I15: 2.219 | J15: -1.869 | K15: 4.214 | M15: 2.4 | N15: 0.068 | O15: 2.419 | P15: -1.475 | Q15: 4.016 | S15: 2.4 | T15: 0.027 | U15: 6.176 | V15: 1.335 | W15: 5.03 | Y15: 2.39 | Z15: 0 | AA15: 1.341 | AB15: -2.697 | AC15: 4.152 | AE15: 2.4 | AF15: 0.013 | AG15: 1.316 | AH15: -1.951 | AI15: 3.369 | AK15: 2.4 | AL15: 0.013 | AM15: 1.3 | AN15: -0.024 | AO15: 1.371 | AQ15: 2.42 | AR15: 0.694 | AS15: 6.259 | AT15: 6.013 | AU15: 0.258 | AW15: 2.4 | AX15: 0.598 | AY15: 5.047 | AZ15: 4.859 | BA15: 0.197 | BC15: 2.4 | BD15: 0.68 | BE15: 6.567 | BF15: 6.407 | BG15: 0.169 | BI15: 2.39 | BJ15: 0.696 | BK15: 2.158 | BL15: 2.127 | BM15: 0.032 | BO15: 2.4 | BP15: 5.771 | BQ15: 1.358 | BR15: 4.277 | BT15: 2.4 | BU15: 4.29 | BV15: 1.297 | BW15: 2.876
A16: 2.59 | B16: 0 | C16: 6.593 | D16: 1.288 | E16: 5.507 | G16: 2.6 | H16: 0.19 | I16: 1.6 | J16: -2.469 | K16: 4.186 | M16: 2.6 | N16: 0 | O16: 3.558 | P16: -0.332 | Q16: 4.023 | S16: 2.6 | T16: 0.118 | U16: 2.986 | V16: -1.856 | W16: 4.994 | AQ16: 2.62 | AR16: 0.53 | AS16: 5.463 | AT16: 5.221 | AU16: 0.255 | AW16: 2.6 | AX16: 0.49 | AY16: 5.737 | AZ16: 5.566 | BA16: 0.18 | BC16: 2.63 | BD16: 0.585 | BE16: 2.301 | BF16: 2.163 | BG16: 0.143 | BI16: 2.59 | BJ16: 0.517 | BK16: 1.309 | BL16: 1.284 | BM16: 0.026 | BO16: 2.6 | BP16: 5.776 | BQ16: 1.399 | BR16: 4.241 | BT16: 2.6 | BU16: 4.306 | BV16: 1.312 | BW16: 2.876
A17: 2.79 | B17: 0.027 | C17: 6.242 | D17: 0.981 | E17: 5.461 | G17: 2.8 | H17: 0.19 | I17: 1.311 | J17: -2.66 | K17: 4.085 | M17: 2.8 | N17: 0.04 | O17: 3.336 | P17: -0.546 | Q17: 4.013 | S17: 2.8 | T17: 0.118 | U17: 2.673 | V17: -2.157 | W17: 4.973 | AQ17: 2.82 | AR17: 0.367 | AS17: 5.587 | AT17: 2.003 | AU17: 3.732 | AW17: 2.8 | AX17: 0.53 | AY17: 2.293 | AZ17: 2.165 | BA17: 0.134 | BC17: 2.81 | BD17: 0.653 | BE17: 1.316 | BF17: 1.249 | BG17: 0.069 | BI17: 2.79 | BJ17: 0.517 | BK17: 1.31 | BL17: 1.285 | BM17: 0.026 | BO17: 2.79 | BP17: 5.792 | BQ17: 1.343 | BR17: 4.314 | BT17: 2.8 | BU17: 4.329 | BV17: 1.311 | BW17: 2.901
A18: 2.99 | B18: 0 | C18: 5.751 | D18: 0.521 | E18: 5.416 | G18: 3 | H18: 0.081 | I18: 1.319 | J18: -2.624 | K18: 4.056 | M18: 3 | N18: 0.027 | O18: 3.42 | P18: -0.439 | Q18: 3.989 | S18: 3.01 | T18: 0.027 | U18: 2.394 | V18: -2.373 | W18: 4.905 | AQ18: 3.02 | AR18: 0.367 | AS18: 6.006 | AT18: 4.361 | AU18: 1.722 | AW18: 3 | AX18: 0.381 | AY18: 1.309 | AZ18: 1.168 | BA18: 0.147 | BC18: 3.01 | BD18: 0.367 | BE18: 1.377 | BF18: 1.332 | BG18: 0.047 | BI18: 2.99 | BJ18: 0.231 | BK18: 1.311 | BL18: 1.285 | BM18: 0.027 | BO18: 3 | BP18: 5.799 | BQ18: 1.361 | BR18: 4.302 | BT18: 3 | BU18: 4.343 | BV18: 1.325 | BW18: 2.901
A19: 3.19 | B19: 0 | C19: 6.55 | D19: 1.444 | E19: 5.292 | G19: 3.2 | H19: 0 | I19: 1.317 | J19: -2.589 | K19: 4.017 | M19: 3.2 | N19: 0.027 | O19: 3.292 | P19: -0.558 | Q19: 3.979 | S19: 3.21 | T19: 0 | U19: 2.193 | V19: -2.553 | W19: 4.881 | AQ19: 3.22 | AR19: 0.326 | AS19: 6.671 | AT19: 5.42 | AU19: 1.313 | AW19: 3.2 | AX19: 0.381 | AY19: 1.557 | AZ19: 1.404 | BA19: 0.159 | BC19: 3.22 | BD19: 0.367 | BE19: 1.302 | BF19: 1.262 | BG19: 0.042 | BI19: 3.19 | BJ19: 0.04 | BK19: 1.321 | BL19: 1.297 | BM19: 0.025 | BO19: 3.19 | BP19: 5.797 | BQ19: 1.347 | BR19: 4.312 | BT19: 3.2 | BU19: 4.359 | BV19: 1.328 | BW19: 2.912
A20: 3.39 | B20: 0 | C20: 5.421 | D20: 0.307 | E20: 5.306 | M20: 3.4 | N20: 0.04 | O20: 3.484 | P20: -0.356 | Q20: 3.971 | S20: 3.41 | T20: 0.027 | U20: 1.308 | V20: -3.419 | W20: 4.852 | AQ20: 3.42 | AR20: 0.353 | AS20: 5.793 | AT20: 5.177 | AU20: 0.645 | AW20: 3.4 | AX20: 0.136 | AY20: 1.329 | AZ20: 1.18 | BA20: 0.155 | BC20: 3.42 | BD20: 0.136 | BE20: 1.31 | BF20: 1.262 | BG20: 0.05 | BI20: 3.39 | BJ20: 0 | BK20: 1.312 | BL20: 1.285 | BM20: 0.028 | BO20: 3.4 | BP20: 5.803 | BQ20: 1.341 | BR20: 4.326 | BT20: 3.4 | BU20: 4.359 | BV20: 1.316 | BW20: 2.924
A21: 3.6 | B21: 0 | C21: 3.032 | D21: -2.037 | E21: 5.22 | M21: 3.6 | N21: 0.068 | O21: 5.239 | P21: 1.383 | Q21: 4.001 | S21: 3.61 | T21: 0.013 | U21: 1.329 | V21: -3.383 | W21: 4.836 | AQ21: 3.62 | AR21: 0.49 | AS21: 5.793 | AT21: 5.614 | AU21: 0.188 | AW21: 3.6 | AX21: 0.04 | AY21: 1.32 | AZ21: 1.168 | BA21: 0.158 | BO21: 3.6 | BP21: 5.804 | BQ21: 1.354 | BR21: 4.314 | BT21: 3.6 | BU21: 4.342 | BV21: 1.311 | BW21: 2.912
A22: 3.8 | B22: 0 | C22: 2.843 | D22: -2.205 | E22: 5.197 | M22: 3.8 | N22: 0.108 | O22: 4.778 | P22: 0.888 | Q22: 4.032 | AQ22: 3.82 | AR22: 0.68 | AS22: 6.211 | AT22: 6.057 | AU22: 0.162 | AW22: 3.8 | AX22: 0 | AY22: 1.317 | AZ22: 1.168 | BA22: 0.155 | BO22: 3.79 | BP22: 5.799 | BQ22: 1.35 | BR22: 4.314 | BT22: 3.8 | BU22: 4.317 | BV22: 1.323 | BW22: 2.877
A23: 4 | B23: 0 | C23: 2.625 | D23: -2.374 | E23: 5.142 | M23: 4 | N23: 0.081 | O23: 4.614 | P23: 0.758 | Q23: 3.998 | AQ23: 4.02 | AR23: 0.68 | AS23: 5.419 | AT23: 5.31 | AU23: 0.114 | BO23: 3.99 | BP23: 5.792 | BQ23: 1.354 | BR23: 4.301 | BT23: 4 | BU23: 4.286 | BV23: 1.317 | BW23: 2.852
A24: 4.2 | B24: 0 | C24: 2.289 | D24: -2.734 | E24: 5.163 | M24: 4.2 | N24: 0.081 | O24: 8.155 | P24: 4.296 | Q24: 4.034 | AQ24: 4.22 | AR24: 0.721 | AS24: 6.149 | AT24: 6.082 | AU24: 0.07 | BO24: 4.19 | BP24: 5.786 | BQ24: 1.349 | BR24: 4.302 | BT24: 4.2 | BU24: 4.257 | BV24: 1.312 | BW24: 2.828
A25: 4.4 | B25: 0 | C25: 2.131 | D25: -2.877 | E25: 5.147 | M25: 4.4 | N25: 0.136 | O25: 7.508 | P25: 3.528 | Q25: 4.153 | AQ25: 4.42 | AR25: 0.68 | AS25: 6.15 | AT25: 6.075 | AU25: 0.079 | BO25: 4.39 | BP25: 5.789 | BQ25: 1.352 | BR25: 4.302 | BT25: 4.4 | BU25: 4.225 | BV25: 1.305 | BW25: 2.805
A26: 4.6 | B26: 0 | C26: 2.179 | D26: -2.843 | E26: 5.159 | M26: 4.6 | N26: 0.081 | O26: 6.586 | P26: 2.497 | Q26: 4.26 | AQ26: 4.62 | AR26: 0.707 | AS26: 5.743 | AT26: 5.692 | AU26: 0.054 | BT26: 4.6 | BU26: 4.218 | BV26: 1.322 | BW26: 2.78
A27: 4.8 | B27: 0 | C27: 2.187 | D27: -2.831 | E27: 5.155 | M27: 4.8 | N27: 0.04 | O27: 7.078 | P27: 2.988 | Q27: 4.266 | AQ27: 4.82 | AR27: 0.612 | AS27: 4.85 | AT27: 4.8 | AU27: 0.053 | BT27: 4.8 | BU27: 4.198 | BV27: 1.54 | BW27: 2.54
A28: 5 | B28: 0 | C28: 2.174 | D28: -2.853 | E28: 5.167 | M28: 5 | N28: 0.068 | O28: 7.227 | P28: 3.083 | Q28: 4.321 | AQ28: 5.02 | AR28: 0.612 | AS28: 5.983 | AT28: 5.925 | AU28: 0.061 | BT28: 5 | BU28: 4.205 | BV28: 1.321 | BW28: 2.768
A29: 5.2 | B29: 0 | C29: 2.175 | D29: -2.854 | E29: 5.168 | M29: 5.2 | N29: 0.068 | O29: 6.802 | P29: 2.614 | Q29: 4.365 | AQ29: 5.22 | AR29: 0.558 | AS29: 6.569 | AT29: 6.507 | AU29: 0.065 | BT29: 5.2 | BU29: 4.198 | BV29: 1.315 | BW29: 2.769
A30: 5.4 | B30: 0 | C30: 2.175 | D30: -2.854 | E30: 5.168 | M30: 5.4 | N30: 0.054 | O30: 7.2 | P30: 2.958 | Q30: 4.417 | AQ30: 5.42 | AR30: 0.503 | AS30: 6.345 | AT30: 6.276 | AU30: 0.072 | BT30: 5.4 | BU30: 4.206 | BV30: 1.31 | BW30: 2.781
A31: 5.6 | B31: 0 | C31: 2.914 | D31: -2.111 | E31: 5.17 | M31: 5.6 | N31: 0.122 | O31: 6.413 | P31: 2.193 | Q31: 4.393 | AQ31: 5.62 | AR31: 0.462 | AS31: 6.497 | AT31: 6.43 | AU31: 0.07 | BT31: 5.6 | BU31: 4.203 | BV31: 1.308 | BW31: 2.781
A32: 5.8 | B32: 0 | C32: 8.497 | D32: 3.586 | E32: 5.108 | M32: 5.8 | N32: 0.136 | O32: 2.682 | P32: -1.618 | Q32: 4.435 | AQ32: 5.82 | AR32: 0.435 | AS32: 6.4 | AT32: 6.345 | AU32: 0.058 | BT32: 5.8 | BU32: 4.216 | BV32: 1.308 | BW32: 2.793
A33: 6 | B33: 0 | C33: 10.839 | D33: 5.951 | E33: 5.13 | M33: 6 | N33: 0.163 | O33: 2.839 | P33: -1.391 | Q33: 4.365 | AQ33: 6.02 | AR33: 0.435 | AS33: 6.949 | AT33: 6.891 | AU33: 0.061 | BT33: 6 | BU33: 4.236 | BV33: 1.352 | BW33: 2.77
A34: 6.2 | B34: 0.027 | C34: 8.005 | D34: 3.098 | E34: 5.112 | M34: 6.2 | N34: 0.163 | O34: 8.091 | P34: 3.988 | Q34: 4.292 | AQ34: 6.22 | AR34: 0.449 | AS34: 6.717 | AT34: 6.662 | AU34: 0.058 | BT34: 6.2 | BU34: 4.353 | BV34: 1.322 | BW34: 2.913
A35: 6.4 | B35: 0.027 | C35: 6.165 | D35: 1.251 | E35: 5.107 | M35: 6.4 | N35: 0.149 | O35: 5.99 | P35: 1.877 | Q35: 4.274 | AQ35: 6.42 | AR35: 0.422 | AS35: 6.62 | AT35: 6.573 | AU35: 0.049 | BT35: 6.4 | BU35: 4.496 | BV35: 1.331 | BW35: 3.045
A36: 6.6 | B36: 0.04 | C36: 5.346 | D36: 0.461 | E36: 5.071 | M36: 6.6 | N36: 0.217 | O36: 9.655 | P36: 5.622 | Q36: 4.243 | AQ36: 6.62 | AR36: 0.462 | AS36: 6.545 | AT36: 6.486 | AU36: 0.062 | BT36: 6.6 | BU36: 4.612 | BV36: 1.325 | BW36: 3.166
A37: 6.8 | B37: 0.027 | C37: 6.036 | D37: 1.161 | E37: 5.049 | M37: 6.8 | N37: 0.204 | O37: 6.712 | P37: 2.684 | Q37: 4.2 | AQ37: 6.82 | AR37: 0.422 | AS37: 6.361 | AT37: 6.319 | AU37: 0.045 | BT37: 6.8 | BU37: 4.615 | BV37: 1.327 | BW37: 3.165
... A43: 8 | B43: 0 | C43: 1.343 | D43: -3.262 | E43: 4.729 | M43: 8 | N43: 0 | O43: 1.322 | P43: -2.493 | Q43: 3.925 | AQ43: 8.02 | AR43: 0.449 | AS43: 6.17 | AT43: 6.143 | AU43: 0.029 | BT43: 8 | BU43: 5.181 | BV43: 1.343 | BW43: 3.709
AQ44: 8.22 | AR44: 0.408 | AS44: 6.215 | AT44: 6.191 | AU44: 0.025 | BT44: 8.2 | BU44: 5.163 | BV44: 1.337 | BW44: 3.696
AQ45: 8.42 | AR45: 0.381 | AS45: 9.776 | AT45: 9.751 | AU45: 0.027 | BT45: 8.4 | BU45: 5.104 | BV45: 1.339 | BW45: 3.636
...

Sheet Charts - Overview
A1: Whole log: sun phase, move into shade, idle, shade phase

Sheet Charts - Sun
A1: Sun runs: from rest to full throttle (7 runs)

Sheet Charts - Shade
A1: Shade runs: from rest to full throttle (4 runs)

Sheet Charts - Load vs PV
A1: Load power vs PV power for every run (orange = PV, blue = load). Load above PV = the battery supplies the difference.

Sheet Charts - Charging
A1: Stationary charging in the sun: PV power vs electronics load vs power into the battery
